Workbook

Sheet 01_SYSTEM_SETTINGS
A1: DYNASTY ACCOUNTING OS v1.0 — SYSTEM SETTINGS
A3: Setting | B3: Value | C3: Notes
A4: Company Name | B4: Shylow Thompson LLC
A5: Primary Entity | B5: Shylow Thompson LLC
A6: Fiscal Year Start | B6: 01/01/2026
A7: Fiscal Year End | B7: 12/31/2026
A8: Accounting Method | B8: Accrual | C8: GAAP standard
A9: Base Currency | B9: USD
A10: Version | B10: 1.0
A11: Build Date | B11: 05/29/2026
A12: Next Review | B12: 12/31/2026
A13: Tax ID | B13: [ENTER EIN] | C13: Federal EIN
A14: State | B14: Missouri
A15: Chart of Accounts Version | B15: RE-COA-2026

Sheet 02_USERS_ROLES
A1: DYNASTY ACCOUNTING OS — USERS & ROLES
A3: User_ID | B3: Full_Name | C3: Role | D3: Entity_Access | E3: Permissions | F3: Last_Login | G3: Status | H3: Notes
A4: U001 | B4: Shylow Thompson | C4: CEO / Owner | D4: All Entities | E4: Full Access | F4: 05/29/2026 | G4: Active | H4: Primary user
A5: U002 | B5: Accountant | C5: Controller | D5: Shylow Thompson LLC | E5: Read/Write | G5: Active
A6: U003 | B6: Investor | C6: Investor Portal | D6: Assigned Deals Only | E6: Read Only | G6: Active

Sheet 03_AUDIT_LOG
A1: DYNASTY ACCOUNTING OS — AUDIT LOG
A3: Log_ID | B3: Timestamp | C3: User_ID | D3: User_Name | E3: Sheet_Modified | F3: Cell_Reference | G3: Old_Value | H3: New_Value | I3: Action_Type | J3: Notes
A4: AL001 | B4: 05/29/2026 09:00 | C4: U001 | D4: Shylow Thompson | E4: 01_SYSTEM_SETTINGS | F4: B4 | H4: Shylow Thompson LLC | I4: INITIALIZE | J4: System initialization
A5: AL002 | B5: 05/29/2026 09:01 | C5: U001 | D5: Shylow Thompson | E5: 50_PROPERTY_MASTER | F5: B4 | H5: 502 Buckley | I5: CREATE | J5: Added 502 Buckley property

Sheet 04_ENTITY_MANAGER
A1: DYNASTY ACCOUNTING OS — ENTITY MANAGER
A3: Entity_ID | B3: Entity_Name | C3: Entity_Type | D3: EIN | E3: State | F3: Formation_Date | G3: Primary_Contact | H3: Role | I3: Status | J3: Notes
A4: E001 | B4: Shylow Thompson LLC | C4: Operating LLC | D4: [EIN] | E4: Missouri | G4: Shylow Thompson | H4: CEO | I4: Active | J4: Primary operating entity
A5: E002 | B5: Dynasty OS | C5: Tech/SaaS LLC | D5: [EIN] | E5: Missouri | G5: Shylow Thompson | H5: CEO | I5: Active | J5: Software operations
A6: E003 | B6: KhakiSol | C6: Brand/Creative LLC | D6: [EIN] | E6: Missouri | G6: Shylow Thompson | H6: CEO | I6: Active | J6: Creative & brand
A7: E004 | B7: 502 Buckley LLC | C7: Property LLC | D7: [EIN] | E7: Missouri | G7: Shylow Thompson | H7: Manager | I7: Active | J7: Property holding entity

Sheet 05_DASHBOARD_HOME
A1: DYNASTY ACCOUNTING OS — COMMAND CENTER
A3: QUICK NAVIGATION
A4: Section | B4: Sheet Name | C4: Description | D4: Tab Color
A5: SYSTEM | B5: 01_SYSTEM_SETTINGS | C5: Global configuration | D5: Dark Gray
A6: SYSTEM | B6: 02_USERS_ROLES | C6: User access management | D6: Dark Gray
A7: SYSTEM | B7: 03_AUDIT_LOG | C7: Change history | D7: Dark Gray
A8: SYSTEM | B8: 04_ENTITY_MANAGER | C8: Business entities | D8: Dark Gray
A9: SYSTEM | B9: 05_DASHBOARD_HOME | C9: This navigation screen | D9: Dark Gray
A10: ACCOUNTING | B10: 10_CHART_OF_ACCOUNTS | C10: Full COA 1000-6999 | D10: Dark Blue
A11: ACCOUNTING | B11: 11_JOURNAL_ENTRIES | C11: Double-entry transactions | D11: Dark Blue
A12: ACCOUNTING | B12: 12_GENERAL_LEDGER | C12: Account activity detail | D12: Dark Blue
A13: ACCOUNTING | B13: 13_TRIAL_BALANCE | C13: Debit/credit balance check | D13: Dark Blue
A14: ACCOUNTING | B14: 14_BALANCE_SHEET | C14: Assets = Liabilities + Equity | D14: Dark Blue
A15: ACCOUNTING | B15: 15_INCOME_STATEMENT | C15: Revenue - Expenses = Net Income | D15: Dark Blue
... A57: EXECUTIVE | B57: 94_EXECUTIVE_REPORT | C57: Executive summary report | D57: Gold
A60: SYSTEM STATUS
A61: Metric | B61: Value | C61: Status
A62: Last Updated | B62: 05/29/2026 | C62: Current
A63: Formula Errors | B63: 0 | C63: OK
A64: Accounting Balance | B64: Balanced | C64: OK
A65: Active Properties | B65: 1 | C65: Active
A66: Active Deals | B66: 1 | C66: Active
A67: Version | B67: 1.0 | C67: Current

Sheet 10_CHART_OF_ACCOUNTS
A1: CHART OF ACCOUNTS — Dynasty Accounting OS v1.0
A3: Account_Number | B3: Account_Name | C3: Account_Type | D3: Sub_Type | E3: Normal_Balance | F3: Description | G3: Active | H3: Entity
A4: 1000 | B4: Cash — Operating Account | C4: Asset | D4: Current Asset | E4: Debit | F4: Primary operating checking | G4: Yes | H4: All
A5: 1010 | B5: Cash — Savings Account | C5: Asset | D5: Current Asset | E5: Debit | F5: Business savings | G5: Yes | H5: All
A6: 1020 | B6: Cash — Reserve Fund | C6: Asset | D6: Current Asset | E6: Debit | F6: Capital reserves | G6: Yes | H6: All
A7: 1030 | B7: Cash — Tax Reserve | C7: Asset | D7: Current Asset | E7: Debit | F7: Tax payment reserves | G7: Yes | H7: All
A8: 1040 | B8: Petty Cash | C8: Asset | D8: Current Asset | E8: Debit | F8: Small cash purchases | G8: Yes | H8: All
A9: 1100 | B9: Accounts Receivable | C9: Asset | D9: Current Asset | E9: Debit | F9: Money owed to company | G9: Yes | H9: All
A10: 1110 | B10: AR — Assignment Fees | C10: Asset | D10: Current Asset | E10: Debit | F10: Wholesale assignment receivables | G10: Yes | H10: All
A11: 1120 | B11: AR — Rental Income | C11: Asset | D11: Current Asset | E11: Debit | F11: Rent receivables | G11: Yes | H11: All
A12: 1200 | B12: Prepaid Expenses | C12: Asset | D12: Current Asset | E12: Debit | F12: Prepaid insurance, rent | G12: Yes | H12: All
A13: 1210 | B13: Prepaid Insurance | C13: Asset | D13: Current Asset | E13: Debit | G13: Yes | H13: All
A14: 1300 | B14: Inventory — Land | C14: Asset | D14: Real Estate Inventory | E14: Debit | F14: Land held for sale | G14: Yes | H14: All
A15: 1310 | B15: Inventory — Wholesale Contracts | C15: Asset | D15: Real Estate Inventory | E15: Debit | F15: Contracts under assignment | G15: Yes | H15: All
A16: 1400 | B16: Real Estate — Investment Properties | C16: Asset | D16: Fixed Asset | E16: Debit | F16: Properties held for investment | G16: Yes | H16: All
A17: 1410 | B17: 502 Buckley — Building | C17: Asset | D17: Fixed Asset | E17: Debit | F17: Building value at purchase | G17: Yes | H17: STLLC
A18: 1420 | B18: 502 Buckley — Land | C18: Asset | D18: Fixed Asset | E18: Debit | F18: Land value at purchase | G18: Yes | H18: STLLC
A19: 1430 | B19: Accumulated Depreciation — Buildings | C19: Asset | D19: Fixed Asset | E19: Credit | F19: Contra asset | G19: Yes | H19: All
A20: 1500 | B20: Equipment | C20: Asset | D20: Fixed Asset | E20: Debit | F20: Tools, equipment | G20: Yes | H20: All
A21: 1510 | B21: Vehicles | C21: Asset | D21: Fixed Asset | E21: Debit | F21: Company vehicles | G21: Yes | H21: All
A22: 1520 | B22: Accumulated Depreciation — Equipment | C22: Asset | D22: Fixed Asset | E22: Credit | F22: Contra asset | G22: Yes | H22: All
A23: 1600 | B23: Security Deposits Held | C23: Asset | D23: Other Asset | E23: Debit | F23: Tenant deposits | G23: Yes | H23: All
A24: 1700 | B24: Due from Related Entities | C24: Asset | D24: Other Asset | E24: Debit | F24: Inter-company receivables | G24: Yes | H24: All
A25: 1800 | B25: Investments — Joint Ventures | C25: Asset | D25: Other Asset | E25: Debit | F25: JV investment interests | G25: Yes | H25: All
... A30: 2100 | B30: Credit Cards Payable | C30: Liability | D30: Current Liability | E30: Credit | F30: Credit card balances | G30: Yes | H30: All
A31: 2110 | B31: Chase Business Card | C31: Liability | D31: Current Liability | E31: Credit | G31: Yes | H31: All
A32: 2200 | B32: Accrued Expenses | C32: Liability | D32: Current Liability | E32: Credit | F32: Expenses incurred not yet paid | G32: Yes | H32: All
A33: 2210 | B33: Accrued Interest | C33: Liability | D33: Current Liability | E33: Credit | G33: Yes | H33: All
A34: 2220 | B34: Accrued Payroll | C34: Liability | D34: Current Liability | E34: Credit | G34: Yes | H34: All
A35: 2300 | B35: Security Deposits — Tenant | C35: Liability | D35: Current Liability | E35: Credit | F35: Deposits held for tenants | G35: Yes | H35: All
A36: 2400 | B36: Short-Term Debt | C36: Liability | D36: Current Liability | E36: Credit | F36: Debt due within 12 months | G36: Yes | H36: All
A37: 2500 | B37: Mortgage Payable — 502 Buckley | C37: Liability | D37: Long-Term Liability | E37: Credit | F37: FHA mortgage principal | G37: Yes | H37: STLLC
A38: 2510 | B38: Hard Money Loans | C38: Liability | D38: Long-Term Liability | E38: Credit | F38: Hard money borrowings | G38: Yes | H38: All
A39: 2520 | B39: Private Lender Notes | C39: Liability | D39: Long-Term Liability | E39: Credit | F39: Private money loans | G39: Yes | H39: All
A40: 2530 | B40: Seller Financing | C40: Liability | D40: Long-Term Liability | E40: Credit | F40: Owner carry notes | G40: Yes | H40: All
A41: 2600 | B41: Deferred Revenue | C41: Liability | D41: Long-Term Liability | E41: Credit | F41: Advance rent payments | G41: Yes | H41: All
A42: 2700 | B42: Due to Related Entities | C42: Liability | D42: Long-Term Liability | E42: Credit | F42: Inter-company payables | G42: Yes | H42: All
A43: 2800 | B43: Tax Payable — Income | C43: Liability | D43: Current Liability | E43: Credit | F43: Estimated income taxes | G43: Yes | H43: All
A44: 2810 | B44: Tax Payable — Sales | C44: Liability | D44: Current Liability | E44: Credit | F44: Sales tax collected | G44: Yes | H44: All
A45: 2900 | B45: Other Liabilities | C45: Liability | D45: Other Liability | E45: Credit | F45: Miscellaneous | G45: Yes | H45: All
...

Sheet 11_JOURNAL_ENTRIES
A1: JOURNAL ENTRIES — Double-Entry Accounting Ledger
A3: JE_ID | B3: Date | C3: Description | D3: Debit_Acct | E3: Debit_Name | F3: Debit_Amt | G3: Credit_Acct | H3: Credit_Name | I3: Credit_Amt | J3: Entity | K3: Reference | L3: Posted | M3: Notes
A4: JE001 | B4: 05/01/2026 | C4: Opening Capital Contribution | D4: 1000 | E4: Cash — Operating Account | F4: 25000 | G4: 3030 | H4: Capital Contributions | I4: 25000 | J4: STLLC | K4: OPENING | L4: Yes | M4: Initial capital
A5: JE002 | B5: 05/01/2026 | C5: Purchase 502 Buckley — Building | D5: 1410 | E5: 502 Buckley — Building | F5: 97900 | G5: 2500 | H5: Mortgage Payable — 502 Buckley | I5: 114000 | J5: STLLC | K5: CLOSING-502 | L5: Yes | M5: FHA purchase close
A6: JE003 | B6: 05/01/2026 | C6: Purchase 502 Buckley — Land | D6: 1420 | E6: 502 Buckley — Land | F6: 16100 | G6: 1000 | H6: Cash — Operating Account | I6: 4500 | J6: STLLC | K6: CLOSING-502 | L6: Yes | M6: Land allocation + closing costs
A7: JE004 | B7: 05/01/2026 | C7: Acquisition Closing Costs | D7: 5010 | E7: Acquisition Costs | F7: 4500 | G7: 1000 | H7: Cash — Operating Account | I7: 0 | J7: STLLC | K7: CLOSING-502 | L7: Yes | M7: Included in JE003 credit
A8: JE005 | B8: 05/15/2026 | C8: Rehab Materials — Demo Phase | D8: 5110 | E8: Rehab — Materials | F8: 3500 | G8: 1000 | H8: Cash — Operating Account | I8: 3500 | J8: STLLC | K8: INV-001 | L8: Yes | M8: Demo phase materials
A9: JE006 | B9: 05/20/2026 | C9: Rehab Labor — Contractor Draw 1 | D9: 5100 | E9: Rehab — Labor | F9: 8000 | G9: 2010 | H9: AP — Contractors | I9: 8000 | J9: STLLC | K9: INV-002 | L9: Yes | M9: First labor draw
A10: JE007 | B10: 05/25/2026 | C10: PropWire Subscription | D10: 6120 | E10: Marketing — Software | F10: 299 | G10: 2110 | H10: Chase Business Card | I10: 299 | J10: STLLC | K10: CC-001 | L10: Yes | M10: Monthly subscription
A13: BALANCE CHECK (Posted): | E13: Total Debits: | F13: =SUMIF(L4:L100,"Yes",F4:F100) -> 155299 | H13: Total Credits: | I13: =SUMIF(L4:L100,"Yes",I4:I100) -> 155299
E14: Difference (must = 0): | F14: =F13-I13 -> 0

Sheet 12_GENERAL_LEDGER
A1: GENERAL LEDGER — Account Activity Detail
A3: Select Account Number: | C3: 1000
A5: GL_ID | B5: Date | C5: Account_Number | D5: Account_Name | E5: Description | F5: JE_Reference | G5: Debit | H5: Credit | I5: Entity
A6: GL-001 | B6: 05/01/2026 | C6: 1000 | D6: Cash — Operating Account | E6: Opening capital contribution | F6: JE001 | G6: 25000 | H6: 0 | I6: STLLC

Sheet 13_TRIAL_BALANCE
A1: TRIAL BALANCE — As of 05/29/2026
A3: Account_Number | B3: Account_Name | C3: Account_Type | D3: Debit | E3: Credit
A4: 1000 | B4: Cash — Operating Account | C4: Asset | D4: =SUMIF('11_JOURNAL_ENTRIES'!D:D,A4,'11_JOURNAL_ENTRIES'!F:F) -> 25000 | E4: =SUMIF('11_JOURNAL_ENTRIES'!H:H,A4,'11_JOURNAL_ENTRIES'!I:I) -> 0
A5: 1410 | B5: 502 Buckley — Building | C5: Asset | D5: =SUMIF('11_JOURNAL_ENTRIES'!D:D,A5,'11_JOURNAL_ENTRIES'!F:F) -> 97900 | E5: =SUMIF('11_JOURNAL_ENTRIES'!H:H,A5,'11_JOURNAL_ENTRIES'!I:I) -> 0
A6: 1420 | B6: 502 Buckley — Land | C6: Asset | D6: =SUMIF('11_JOURNAL_ENTRIES'!D:D,A6,'11_JOURNAL_ENTRIES'!F:F) -> 16100 | E6: =SUMIF('11_JOURNAL_ENTRIES'!H:H,A6,'11_JOURNAL_ENTRIES'!I:I) -> 0
A7: 2010 | B7: AP — Contractors | C7: Liability | D7: =SUMIF('11_JOURNAL_ENTRIES'!D:D,A7,'11_JOURNAL_ENTRIES'!F:F) -> 0 | E7: =SUMIF('11_JOURNAL_ENTRIES'!H:H,A7,'11_JOURNAL_ENTRIES'!I:I) -> 0
A8: 2110 | B8: Chase Business Card | C8: Liability | D8: =SUMIF('11_JOURNAL_ENTRIES'!D:D,A8,'11_JOURNAL_ENTRIES'!F:F) -> 0 | E8: =SUMIF('11_JOURNAL_ENTRIES'!H:H,A8,'11_JOURNAL_ENTRIES'!I:I) -> 0
A9: 2500 | B9: Mortgage Payable — 502 Buckley | C9: Liability | D9: =SUMIF('11_JOURNAL_ENTRIES'!D:D,A9,'11_JOURNAL_ENTRIES'!F:F) -> 0 | E9: =SUMIF('11_JOURNAL_ENTRIES'!H:H,A9,'11_JOURNAL_ENTRIES'!I:I) -> 0
A10: 3030 | B10: Capital Contributions | C10: Equity | D10: =SUMIF('11_JOURNAL_ENTRIES'!D:D,A10,'11_JOURNAL_ENTRIES'!F:F) -> 0 | E10: =SUMIF('11_JOURNAL_ENTRIES'!H:H,A10,'11_JOURNAL_ENTRIES'!I:I) -> 0
A11: 5010 | B11: Acquisition Costs | C11: COGS | D11: =SUMIF('11_JOURNAL_ENTRIES'!D:D,A11,'11_JOURNAL_ENTRIES'!F:F) -> 4500 | E11: =SUMIF('11_JOURNAL_ENTRIES'!H:H,A11,'11_JOURNAL_ENTRIES'!I:I) -> 0
A12: 5100 | B12: Rehab — Labor | C12: COGS | D12: =SUMIF('11_JOURNAL_ENTRIES'!D:D,A12,'11_JOURNAL_ENTRIES'!F:F) -> 8000 | E12: =SUMIF('11_JOURNAL_ENTRIES'!H:H,A12,'11_JOURNAL_ENTRIES'!I:I) -> 0
A13: 5110 | B13: Rehab — Materials | C13: COGS | D13: =SUMIF('11_JOURNAL_ENTRIES'!D:D,A13,'11_JOURNAL_ENTRIES'!F:F) -> 3500 | E13: =SUMIF('11_JOURNAL_ENTRIES'!H:H,A13,'11_JOURNAL_ENTRIES'!I:I) -> 0
A14: 6120 | B14: Marketing — Software | C14: Expense | D14: =SUMIF('11_JOURNAL_ENTRIES'!D:D,A14,'11_JOURNAL_ENTRIES'!F:F) -> 299 | E14: =SUMIF('11_JOURNAL_ENTRIES'!H:H,A14,'11_JOURNAL_ENTRIES'!I:I) -> 0
A16: TOTAL | D16: =SUM(D4:D15) -> 155299 | E16: =SUM(E4:E15) -> 0
A17: DIFFERENCE (must = 0) | D17: =D16-E16 -> 155299

Sheet 14_BALANCE_SHEET
A1: BALANCE SHEET — As of 05/29/2026
A3: ASSETS
A4: CURRENT ASSETS
A5: Cash — Operating Account | C5: 17200
A6: Accounts Receivable | C6: 0
A7: Prepaid Expenses | C7: 0
B8: Total Current Assets | C8: =SUM(C5:C7) -> 17200
A9: FIXED ASSETS
A10: 502 Buckley — Building | C10: 97900
A11: 502 Buckley — Land | C11: 16100
A12: Accumulated Depreciation | C12: 0
B13: Total Fixed Assets | C13: =SUM(C10:C12) -> 114000
A14: TOTAL ASSETS | C14: =C8+C13 -> 131200
A16: LIABILITIES & EQUITY
A17: CURRENT LIABILITIES
A18: AP — Contractors | C18: 8000
A19: Chase Business Card | C19: 299
A20: Accrued Expenses | C20: 0
B21: Total Current Liabilities | C21: =SUM(C18:C20) -> 8299
A22: LONG-TERM LIABILITIES
A23: Mortgage Payable — 502 Buckley | C23: 114000
B24: Total Long-Term Liabilities | C24: =SUM(C23:C23) -> 114000
A25: TOTAL LIABILITIES | C25: =C22+C26 -> 0
A26: OWNER'S EQUITY
A27: Capital Contributions | C27: 25000
A28: Members Draws | C28: 0
A29: Retained Earnings | C29: -8799
B30: Total Owner's Equity | C30: =SUM(C27:C29) -> 16201
A31: TOTAL LIABILITIES + EQUITY | C31: =C25+C29 -> -8799
A33: BALANCE CHECK (must = $0): | C33: =C14-C31 -> 139999

Sheet 15_INCOME_STATEMENT
A1: INCOME STATEMENT — Period: Jan 2026 — May 2026
A3: REVENUE
A4: Wholesale Assignment Fees | C4: 0
A5: Flip Profits | C5: 0
A6: Rental Income | C6: 0
A7: Other Revenue | C7: 0
B8: TOTAL REVENUE | C8: =SUM(C4:C7) -> 0
A10: COST OF GOODS SOLD (COGS)
A11: Acquisition Costs | C11: 4500
A12: Rehab — Labor | C12: 8000
A13: Rehab — Materials | C13: 3500
A14: Holding Costs | C14: 1080
A15: Assignment Costs | C15: 0
B16: TOTAL COGS | C16: =SUM(C10:C15) -> 17080
B17: GROSS PROFIT | C17: =C8-C16 -> -17080
B18: Gross Margin % | C18: =IF(C8=0,0,C17/C8) -> 0
A20: OPERATING EXPENSES
A21: Marketing | C21: 299
A22: Professional Fees | C22: 0
A23: Software & Technology | C23: 0
A24: Insurance | C24: 0
A25: Vehicle & Travel | C25: 0
A26: Bank Fees | C26: 0
A27: Other Expenses | C27: 0
B28: TOTAL OPERATING EXPENSES | C28: =SUM(C20:C27) -> 299
B29: OPERATING INCOME (EBIT) | C29: =C17-C28 -> -17379
A31: BELOW-THE-LINE
A32: Interest Expense | C32: 0
A33: Depreciation | C33: 0
B35: NET INCOME | C35: =C29-SUM(C31:C33) -> -17379

Sheet 16_CASH_FLOW
A1: CASH FLOW STATEMENT — YTD 2026
A3: A. OPERATING ACTIVITIES
A4: Net Income | C4: -16379
A5: Add: Depreciation | C5: 0
A6: Changes in Accounts Receivable | C6: 0
A7: Changes in Accounts Payable | C7: 8299
B8: Net Operating Cash Flow | C8: =SUM(C4:C7) -> -8080
A10: B. INVESTING ACTIVITIES
A11: Property Acquisitions | C11: -114000
A12: Rehab Spending | C12: -11500
A13: Proceeds from Property Sales | C13: 0
B14: Net Investing Cash Flow | C14: =SUM(C11:C13) -> -125500
A16: C. FINANCING ACTIVITIES
A17: Mortgage Proceeds | C17: 114000
A18: Mortgage Payments | C18: 0
A19: Capital Contributions | C19: 25000
A20: Owner Draws | C20: 0
B21: Net Financing Cash Flow | C21: =SUM(C17:C20) -> 139000
A24: NET CHANGE IN CASH | C24: =C8+C14+C21 -> 5420
A25: Beginning Cash Balance | C25: 0
A26: ENDING CASH BALANCE | C26: =C24+C25 -> 5420

Sheet 17_BUDGETS
A1: ANNUAL BUDGET — FY 2026
A3: Account_Number | B3: Account_Name | C3: Category | D3: Jan | E3: Feb | F3: Mar | G3: Apr | H3: May | I3: Jun | J3: Jul | K3: Aug | L3: Sep | M3: Oct | N3: Nov | O3: Dec | P3: Annual_Total
A4: 4000 | B4: Wholesale Assignment Fees | C4: Revenue | D4: 5000 | E4: 5000 | F4: 5000 | G4: 5000 | H4: 5000 | I4: 5000 | J4: 5000 | K4: 5000 | L4: 5000 | M4: 5000 | N4: 5000 | O4: 5000 | P4: =SUM(D4:O4) -> 60000
A5: 4020 | B5: Rental Income | C5: Revenue | D5: 0 | E5: 0 | F5: 0 | G5: 0 | H5: 0 | I5: 0 | J5: 0 | K5: 0 | L5: 0 | M5: 0 | N5: 0 | O5: 0 | P5: =SUM(D5:O5) -> 0
A6: 5100 | B6: Rehab — Labor | C6: COGS | D6: 8000 | E6: 8000 | F6: 5000 | G6: 3000 | H6: 2000 | I6: 0 | J6: 0 | K6: 0 | L6: 0 | M6: 0 | N6: 0 | O6: 0 | P6: =SUM(D6:O6) -> 26000
A7: 5110 | B7: Rehab — Materials | C7: COGS | D7: 5000 | E7: 5000 | F7: 3000 | G7: 2000 | H7: 1000 | I7: 0 | J7: 0 | K7: 0 | L7: 0 | M7: 0 | N7: 0 | O7: 0 | P7: =SUM(D7:O7) -> 16000
A8: 5210 | B8: Holding — Mortgage | C8: COGS | D8: 750 | E8: 750 | F8: 750 | G8: 750 | H8: 750 | I8: 750 | J8: 750 | K8: 750 | L8: 750 | M8: 750 | N8: 750 | O8: 750 | P8: =SUM(D8:O8) -> 9000
A9: 5220 | B9: Holding — Insurance | C9: COGS | D9: 100 | E9: 100 | F9: 100 | G9: 100 | H9: 100 | I9: 100 | J9: 100 | K9: 100 | L9: 100 | M9: 100 | N9: 100 | O9: 100 | P9: =SUM(D9:O9) -> 1200
A10: 6100 | B10: Marketing — Digital | C10: Expense | D10: 1500 | E10: 1500 | F10: 1500 | G10: 1500 | H10: 1500 | I10: 1500 | J10: 1500 | K10: 1500 | L10: 1500 | M10: 1500 | N10: 1500 | O10: 1500 | P10: =SUM(D10:O10) -> 18000
A11: 6120 | B11: Marketing — Software | C11: Expense | D11: 299 | E11: 299 | F11: 299 | G11: 299 | H11: 299 | I11: 299 | J11: 299 | K11: 299 | L11: 299 | M11: 299 | N11: 299 | O11: 299 | P11: =SUM(D11:O11) -> 3588
A12: 6300 | B12: Professional Fees — Legal | C12: Expense | D12: 500 | E12: 0 | F12: 500 | G12: 0 | H12: 500 | I12: 0 | J12: 500 | K12: 0 | L12: 500 | M12: 0 | N12: 500 | O12: 0 | P12: =SUM(D12:O12) -> 3000
A13: 6310 | B13: Professional Fees — Accounting | C13: Expense | D13: 250 | E13: 250 | F13: 250 | G13: 250 | H13: 250 | I13: 250 | J13: 250 | K13: 250 | L13: 250 | M13: 250 | N13: 250 | O13: 250 | P13: =SUM(D13:O13) -> 3000
A14: 6400 | B14: Software & Technology | C14: Expense | D14: 200 | E14: 200 | F14: 200 | G14: 200 | H14: 200 | I14: 200 | J14: 200 | K14: 200 | L14: 200 | M14: 200 | N14: 200 | O14: 200 | P14: =SUM(D14:O14) -> 2400
A15: 6500 | B15: Insurance | C15: Expense | D15: 150 | E15: 150 | F15: 150 | G15: 150 | H15: 150 | I15: 150 | J15: 150 | K15: 150 | L15: 150 | M15: 150 | N15: 150 | O15: 150 | P15: =SUM(D15:O15) -> 1800
... A17: 6700 | B17: Bank Fees | C17: Expense | D17: 25 | E17: 25 | F17: 25 | G17: 25 | H17: 25 | I17: 25 | J17: 25 | K17: 25 | L17: 25 | M17: 25 | N17: 25 | O17: 25 | P17: =SUM(D17:O17) -> 300

Sheet 18_BUDGET_VS_ACTUAL
A1: BUDGET VS ACTUAL — YTD 2026
A3: Account_Number | B3: Account_Name | C3: Budget_YTD | D3: Actual_YTD | E3: Variance | F3: Variance_% | G3: Status
A4: 4000 | B4: Wholesale Assignment Fees | C4: 25000 | D4: 0 | E4: =C4-D4 -> 25000 | F4: =IF(C4=0,0,(C4-D4)/C4) -> 1 | G4: =IF(C4=0,"N/A",IF(E4<0,"OVER BUDGET",IF(ABS(F4)<0.1,"ON TRACK","UNDER BUDGET"))) -> UNDER BUDGET
A5: 5100 | B5: Rehab — Labor | C5: 26000 | D5: 8000 | E5: =C5-D5 -> 18000 | F5: =IF(C5=0,0,(C5-D5)/C5) -> 0.69230769 | G5: =IF(C5=0,"N/A",IF(E5<0,"OVER BUDGET",IF(ABS(F5)<0.1,"ON TRACK","UNDER BUDGET"))) -> UNDER BUDGET
A6: 5110 | B6: Rehab — Materials | C6: 16000 | D6: 3500 | E6: =C6-D6 -> 12500 | F6: =IF(C6=0,0,(C6-D6)/C6) -> 0.78125 | G6: =IF(C6=0,"N/A",IF(E6<0,"OVER BUDGET",IF(ABS(F6)<0.1,"ON TRACK","UNDER BUDGET"))) -> UNDER BUDGET
A7: 5210 | B7: Holding — Mortgage | C7: 3750 | D7: 750 | E7: =C7-D7 -> 3000 | F7: =IF(C7=0,0,(C7-D7)/C7) -> 0.8 | G7: =IF(C7=0,"N/A",IF(E7<0,"OVER BUDGET",IF(ABS(F7)<0.1,"ON TRACK","UNDER BUDGET"))) -> UNDER BUDGET
A8: 6100 | B8: Marketing — Digital | C8: 7500 | D8: 0 | E8: =C8-D8 -> 7500 | F8: =IF(C8=0,0,(C8-D8)/C8) -> 1 | G8: =IF(C8=0,"N/A",IF(E8<0,"OVER BUDGET",IF(ABS(F8)<0.1,"ON TRACK","UNDER BUDGET"))) -> UNDER BUDGET
A9: 6120 | B9: Marketing — Software | C9: 1495 | D9: 299 | E9: =C9-D9 -> 1196 | F9: =IF(C9=0,0,(C9-D9)/C9) -> 0.8 | G9: =IF(C9=0,"N/A",IF(E9<0,"OVER BUDGET",IF(ABS(F9)<0.1,"ON TRACK","UNDER BUDGET"))) -> UNDER BUDGET
A10: 6300 | B10: Professional Fees — Legal | C10: 1500 | D10: 0 | E10: =C10-D10 -> 1500 | F10: =IF(C10=0,0,(C10-D10)/C10) -> 1 | G10: =IF(C10=0,"N/A",IF(E10<0,"OVER BUDGET",IF(ABS(F10)<0.1,"ON TRACK","UNDER BUDGET"))) -> UNDER BUDGET
A11: 6310 | B11: Professional Fees — Accounting | C11: 1250 | D11: 0 | E11: =C11-D11 -> 1250 | F11: =IF(C11=0,0,(C11-D11)/C11) -> 1 | G11: =IF(C11=0,"N/A",IF(E11<0,"OVER BUDGET",IF(ABS(F11)<0.1,"ON TRACK","UNDER BUDGET"))) -> UNDER BUDGET

Sheet 20_BANK_ACCOUNTS
A1: BANK ACCOUNTS REGISTRY
A3: Account_ID | B3: Bank_Name | C3: Account_Type | D3: Account_Number | E3: Routing_Number | F3: Opening_Balance | G3: Current_Balance | H3: Last_Reconciled | I3: Status | J3: Notes
A4: BA001 | B4: Chase Bank | C4: Business Checking | D4: XXXX-1234 | E4: 021000021 | F4: 0 | G4: 17200 | H4: 05/29/2026 | I4: Active | J4: Primary operating account
A5: BA002 | B5: Chase Bank | C5: Business Savings | D5: XXXX-5678 | E5: 021000021 | F5: 0 | G5: 0 | I5: Active | J5: Reserve fund

Sheet 21_BANK_TRANSACTIONS
A1: BANK TRANSACTIONS FEED
A3: Trans_ID | B3: Date | C3: Account_ID | D3: Description | E3: Amount | F3: Trans_Type | G3: Category | H3: GL_Account | I3: Matched | J3: Reconciled | K3: Reference | L3: Notes
A4: BT001 | B4: 05/01/2026 | C4: BA001 | D4: Capital contribution | E4: 25000 | F4: Deposit | G4: Capital | H4: 3030 | I4: Yes | J4: Yes | K4: WIRE-001 | L4: Opening capital
A5: BT002 | B5: 05/01/2026 | C5: BA001 | D5: 502 Buckley closing costs | E5: -4500 | F5: Withdrawal | G5: Acquisition | H5: 5010 | I5: Yes | J5: Yes | K5: CHECK-001
A6: BT003 | B6: 05/15/2026 | C6: BA001 | D6: Demo materials | E6: -3500 | F6: Withdrawal | G6: Rehab | H6: 5110 | I6: Yes | J6: Yes | K6: CHECK-002
A7: BT004 | B7: 05/25/2026 | C7: BA001 | D7: PropWire subscription | E7: -299 | F7: Withdrawal | G7: Marketing | H7: 6120 | I7: Yes | J7: Yes | K7: CC-001
A8: BT005 | B8: 05/29/2026 | C8: BA001 | D8: Misc income | E8: 500 | F8: Deposit | G8: Other | H8: 4400 | I8: No | J8: No | L8: Pending match

Sheet 22_RECONCILIATION
A1: BANK RECONCILIATION — Chase Business Checking — May 2026
A3: BANK STATEMENT SECTION
A4: Bank Statement Balance | D4: 17200
A5: + Deposits in Transit | D5: 0
A6: - Outstanding Checks | D6: 0
A7: ADJUSTED BANK BALANCE | D7: =D4+D5-D6 -> 17200
A9: BOOK (GL) SECTION
A10: Book Balance (per GL) | D10: =SUMIF('21_BANK_TRANSACTIONS'!C:C,"BA001",'21_BANK_TRANSACTIONS'!E:E) -> 17201
A11: + Interest Earned | D11: 0
A12: - Bank Charges | D12: 0
A13: ADJUSTED BOOK BALANCE | D13: =D10+D11-D12 -> 17201
A15: DIFFERENCE (must = $0) | D15: =D7-D13 -> -1

Sheet 23_CREDIT_CARDS
A1: CREDIT CARD TRANSACTIONS
A3: Trans_ID | B3: Date | C3: Card_Name | D3: Merchant | E3: Amount | F3: Category | G3: GL_Account | H3: Entity | I3: Reimbursable | J3: Reconciled | K3: Notes
A4: CC001 | B4: 05/25/2026 | C4: Chase Business | D4: PropWire | E4: 299 | F4: Marketing Software | G4: 6120 | H4: STLLC | I4: No | J4: No | K4: Monthly sub
A5: CC002 | B5: 05/20/2026 | C5: Chase Business | D5: Home Depot | E5: 450 | F5: Rehab Materials | G5: 5110 | H5: STLLC | I5: No | J5: No | K5: Demo supplies

Sheet 30_CUSTOMERS
A1: CUSTOMER DATABASE
A3: Customer_ID | B3: First_Name | C3: Last_Name | D3: Company | E3: Email | F3: Phone | G3: Address | H3: Customer_Type | I3: Credit_Limit | J3: Outstanding_Balance | K3: Status | L3: Notes
A4: C001 | B4: John | C4: Smith | E4: john@email.com | F4: 314-555-0001 | G4: St. Louis, MO | H4: Buyer | I4: 500000 | J4: 0 | K4: Active | L4: Cash buyer — wholesale deals
A5: C002 | B5: Mary | C5: Johnson | E5: mary@email.com | F5: 314-555-0002 | G5: St. Louis, MO | H5: Tenant | I5: 2000 | J5: 0 | K5: Active | L5: Potential tenant — 502 Buckley

Sheet 31_INVOICES
A1: INVOICE MANAGEMENT
A3: Invoice_ID | B3: Date | C3: Customer_ID | D3: Customer_Name | E3: Property | F3: Description | G3: Amount | H3: Tax | I3: Total | J3: Due_Date | K3: Status | L3: GL_Account | M3: Entity | N3: Notes
A4: INV-001 | B4: 05/29/2026 | C4: C001 | D4: John Smith | F4: Assignment Fee — 123 Main St | G4: 15000 | H4: 0 | I4: =G4+H4 -> 15000 | J4: 06/15/2026 | K4: Pending | L4: 4000 | M4: STLLC

Sheet 32_RECEIVABLES
A1: ACCOUNTS RECEIVABLE TRACKER
A3: AR_ID | B3: Invoice_ID | C3: Customer_ID | D3: Customer_Name | E3: Original_Amount | F3: Amount_Paid | G3: Balance_Due | H3: Invoice_Date | I3: Due_Date | J3: Days_Outstanding | K3: Status
A4: AR001 | B4: INV-001 | C4: C001 | D4: John Smith | E4: 15000 | F4: 0 | G4: =E4-F4 -> 15000 | H4: 05/29/2026 | I4: 06/15/2026 | J4: =IF(K4="Paid",0,MAX(0,TODAY()-I4)) -> 0 | K4: Pending

Sheet 33_AGING_REPORT
A1: ACCOUNTS RECEIVABLE AGING — As of Today
A3: Customer_Name | B3: Current | C3: 1-30 Days | D3: 31-60 Days | E3: 61-90 Days | F3: 90+ Days | G3: Total
A4: John Smith | B4: 15000 | C4: 0 | D4: 0 | E4: 0 | F4: 0 | G4: =SUM(B4:F4) -> 15000
A6: TOTAL | B6: =SUM(B4:B5) -> 15000 | C6: =SUM(C4:C5) -> 0 | D6: =SUM(D4:D5) -> 0 | E6: =SUM(E4:E5) -> 0 | F6: =SUM(F4:F5) -> 0 | G6: =SUM(G4:G5) -> 15000

Sheet 40_VENDORS
A1: VENDOR DATABASE
A3: Vendor_ID | B3: Vendor_Name | C3: Contact_Name | D3: Email | E3: Phone | F3: Address | G3: Vendor_Type | H3: Payment_Terms | I3: W9_On_File | J3: 1099_Required | K3: Outstanding_Balance | L3: Status | M3: Notes
A4: V001 | B4: General Contractor | C4: TBD | E4: 314-555-0100 | F4: St. Louis, MO | G4: Contractor | H4: Net 30 | I4: Yes | J4: Yes | K4: 8000 | L4: Active | M4: Primary rehab contractor
A5: V002 | B5: PropWire | D5: billing@propwire.com | G5: Software | H5: Monthly | I5: No | J5: No | K5: 0 | L5: Active | M5: Lead generation software
A6: V003 | B6: Home Depot | G6: Supplier | H6: Net 0 | I6: No | J6: No | K6: 450 | L6: Active | M6: Materials supplier

Sheet 41_BILLS
A1: BILL MANAGEMENT — Accounts Payable
A3: Bill_ID | B3: Date | C3: Vendor_ID | D3: Vendor_Name | E3: Description | F3: Amount | G3: Due_Date | H3: Status | I3: GL_Account | J3: Property | K3: Entity | L3: Approved_By | M3: Notes
A4: BILL-001 | B4: 05/20/2026 | C4: V001 | D4: General Contractor | E4: Labor — Demo phase 502 Buckley | F4: 8000 | G4: 06/20/2026 | H4: Unpaid | I4: 5100 | J4: 502 Buckley | K4: STLLC | L4: Shylow | M4: Phase 1 labor
A5: BILL-002 | B5: 05/25/2026 | C5: V002 | D5: PropWire | E5: Monthly subscription | F5: 299 | G5: 06/01/2026 | H5: Paid | I5: 6120 | K5: STLLC | L5: Shylow
A6: BILL-003 | B6: 05/20/2026 | C6: V003 | D6: Home Depot | E6: Demo supplies | F6: 450 | G6: 05/20/2026 | H6: Paid | I6: 5110 | J6: 502 Buckley | K6: STLLC | L6: Shylow

Sheet 42_PAYABLES
A1: ACCOUNTS PAYABLE TRACKER
A3: AP_ID | B3: Bill_ID | C3: Vendor_ID | D3: Vendor_Name | E3: Original_Amount | F3: Amount_Paid | G3: Balance_Due | H3: Bill_Date | I3: Due_Date | J3: Days_Outstanding | K3: Status
A4: AP001 | B4: BILL-001 | C4: V001 | D4: General Contractor | E4: 8000 | F4: 0 | G4: =E4-F4 -> 8000 | H4: 05/20/2026 | I4: 06/20/2026 | J4: =IF(K4="Paid",0,MAX(0,TODAY()-I4)) -> 0 | K4: Unpaid
A5: AP002 | B5: BILL-002 | C5: V002 | D5: PropWire | E5: 299 | F5: 299 | G5: =E5-F5 -> 0 | H5: 05/25/2026 | I5: 06/01/2026 | J5: 0 | K5: Paid
A6: AP003 | B6: BILL-003 | C6: V003 | D6: Home Depot | E6: 450 | F6: 450 | G6: =E6-F6 -> 0 | H6: 05/20/2026 | I6: 05/20/2026 | J6: 0 | K6: Paid

Sheet 43_AGING_PAYABLES
A1: ACCOUNTS PAYABLE AGING — As of Today
A3: Vendor_Name | B3: Current | C3: 1-30 Days | D3: 31-60 Days | E3: 61-90 Days | F3: 90+ Days | G3: Total
A4: General Contractor | B4: 8000 | C4: 0 | D4: 0 | E4: 0 | F4: 0 | G4: =SUM(B4:F4) -> 8000
A5: PropWire | B5: 0 | C5: 0 | D5: 0 | E5: 0 | F5: 0 | G5: =SUM(B5:F5) -> 0
A6: Home Depot | B6: 0 | C6: 0 | D6: 0 | E6: 0 | F6: 0 | G6: =SUM(B6:F6) -> 0
A8: TOTAL | B8: =SUM(B4:B7) -> 8000 | C8: =SUM(C4:C7) -> 0 | D8: =SUM(D4:D7) -> 0 | E8: =SUM(E4:E7) -> 0 | F8: =SUM(F4:F7) -> 0 | G8: =SUM(G4:G7) -> 8000

Sheet 50_PROPERTY_MASTER
A1: PROPERTY MASTER — Real Estate Portfolio
A3: Property_ID | B3: Address | C3: City | D3: State | E3: Zip | F3: Property_Type | G3: Status | H3: Purchase_Date | I3: Purchase_Price | J3: Land_Value | K3: Building_Value | L3: Closing_Costs | M3: ARV | N3: Rehab_Budget | O3: Rehab_Actual | P3: Rehab_Variance | Q3: Loan_Balance | R3: Loan_Type | S3: Monthly_Payment | T3: Monthly_Rent | U3: NOI | V3: DSCR | W3: Cap_Rate | X3: Equity | Y3: Exit_Strategy
A4: P001 | B4: 502 Buckley | C4: St. Louis | D4: MO | E4: 63137 | F4: Single Family | G4: Active — Rehab | H4: 05/01/2026 | I4: 114000 | J4: 16100 | K4: 97900 | L4: 4500 | M4: 200000 | N4: 90000 | O4: 11500 | P4: =N4-O4 -> 78500 | Q4: 114000 | R4: FHA | S4: 750 | T4: 0 | U4: =IF(T4>0,T4*0.65*12,0) -> 0 | V4: =IF(S4*12>0,U4/(S4*12),0) -> 0 | W4: =IF(M4>0,U4/M4,0) -> 0 | X4: =M4-Q4 -> 86000 | Y4: BRRR
A5: Notes: | B5: 502 Buckley objectives: Fix crawlspace/floor issues, add basement, add 3rd bedroom. FHA purchase 05/01/2026. Rehab in progress.

Sheet 51_ACQUISITIONS
A1: ACQUISITIONS — Deal Pipeline
A3: Acq_ID | B3: Property | C3: Address | D3: Lead_Source | E3: Lead_Date | F3: Contract_Date | G3: Purchase_Price | H3: ARV | I3: Rehab_Est | J3: MAO | K3: Spread | L3: Under_Contract | M3: Closing_Date | N3: Entity | O3: Deal_Type | P3: Status | Q3: Notes
A4: ACQ001 | B4: 502 Buckley | C4: 502 Buckley, St. Louis MO 63137 | D4: Direct | E4: 04/15/2026 | F4: 04/25/2026 | G4: 114000 | H4: 200000 | I4: 90000 | J4: =H4*0.7-I4 -> 50000 | K4: =J4-G4 -> -64000 | L4: Yes | M4: 05/01/2026 | N4: STLLC | O4: BRRR | P4: Closed | Q4: FHA purchase. Rehab in progress. Objectives: crawlspace, basement, 3rd bedroom

Sheet 52_REHAB_ENGINE
A1: REHAB BUDGET & TRACKER — 502 Buckley St. Louis MO
A3: Work_Order | B3: Category | C3: Scope_of_Work | D3: Budget | E3: Actual | F3: Variance | G3: Pct_Complete | H3: Status | I3: Contractor | J3: Start_Date | K3: End_Date | L3: Notes
A4: WO001 | B4: Demo & Site Prep | C4: Clear structure, remove debris, dumpsters | D4: 5000 | E4: 3500 | F4: =D4-E4 -> 1500 | G4: 70 | H4: In Progress | I4: TBD | J4: 05/10/2026 | K4: 05/31/2026 | L4: Phase 1
A5: WO002 | B5: Crawlspace/Foundation | C5: Fix crawlspace, address foundation issues, add drainage | D5: 12000 | E5: 0 | F5: =D5-E5 -> 12000 | G5: 0 | H5: Pending | I5: TBD | L5: Critical — must complete first
A6: WO003 | B6: Basement Addition | C6: Excavate and pour basement, waterproof | D6: 20000 | E6: 0 | F6: =D6-E6 -> 20000 | G6: 0 | H6: Pending | I6: TBD | L6: Major addition
A7: WO004 | B7: Framing | C7: Add 3rd bedroom framing, structural repairs | D7: 8000 | E7: 0 | F7: =D7-E7 -> 8000 | G7: 0 | H7: Pending | I7: TBD
A8: WO005 | B8: Roofing | C8: Full roof replacement | D8: 6000 | E8: 0 | F8: =D8-E8 -> 6000 | G8: 0 | H8: Pending | I8: TBD
A9: WO006 | B9: Exterior/Siding | C9: Siding, exterior paint, gutters | D9: 4000 | E9: 0 | F9: =D9-E9 -> 4000 | G9: 0 | H9: Pending | I9: TBD
A10: WO007 | B10: Windows & Doors | C10: Replace all windows and exterior doors | D10: 5000 | E10: 0 | F10: =D10-E10 -> 5000 | G10: 0 | H10: Pending | I10: TBD
A11: WO008 | B11: Electrical | C11: Full electrical upgrade, 200 amp panel | D11: 8000 | E11: 0 | F11: =D11-E11 -> 8000 | G11: 0 | H11: Pending | I11: TBD
A12: WO009 | B12: Plumbing | C12: Rough plumbing, fixtures, water heater | D12: 6000 | E12: 0 | F12: =D12-E12 -> 6000 | G12: 0 | H12: Pending | I12: TBD
A13: WO010 | B13: HVAC | C13: New forced air system, ductwork | D13: 7000 | E13: 0 | F13: =D13-E13 -> 7000 | G13: 0 | H13: Pending | I13: TBD
A14: WO011 | B14: Insulation | C14: Full house insulation | D14: 2500 | E14: 0 | F14: =D14-E14 -> 2500 | G14: 0 | H14: Pending | I14: TBD
A15: WO012 | B15: Drywall | C15: Hang, tape, mud, sand throughout | D15: 4000 | E15: 0 | F15: =D15-E15 -> 4000 | G15: 0 | H15: Pending | I15: TBD
A16: WO013 | B16: Interior Doors | C16: All interior doors and hardware | D16: 1500 | E16: 0 | F16: =D16-E16 -> 1500 | G16: 0 | H16: Pending | I16: TBD
A17: WO014 | B17: Flooring | C17: LVP main floor, carpet bedrooms | D17: 5000 | E17: 0 | F17: =D17-E17 -> 5000 | G17: 0 | H17: Pending | I17: TBD
A18: WO015 | B18: Kitchen | C18: Full kitchen — cabinets, counters, backsplash | D18: 8000 | E18: 0 | F18: =D18-E18 -> 8000 | G18: 0 | H18: Pending | I18: TBD
... A30: WO027 | B30: Inspections | C30: All required inspections | D30: 500 | E30: 0 | F30: =D30-E30 -> 500 | G30: 0 | H30: Pending | I30: TBD
A31: WO028 | B31: Contingency 10% | C31: 10% contingency reserve | D31: =SUM(D4:D30)*0.1 -> 12750 | E31: 0 | F31: =D31-E31 -> 12750
A32: WO029 | B32: GC Overhead 10% | C32: General contractor markup | D32: =SUM(D4:D30)*0.1 -> 12750 | E32: 0 | F32: =D32-E32 -> 12750
A33: WO030 | B33: Change Orders | C33: Approved change orders | D33: 0 | E33: 8000 | F33: =D33-E33 -> -8000
A35: TOTAL REHAB BUDGET | D35: =SUM(D4:D33) -> 153000 | E35: =SUM(E4:E33) -> 11500 | F35: =D35-E35 -> 141500
A36: REHAB HEALTH SCORE: | D36: =IF(E35>D35,"RED — OVER BUDGET",IF(E35/D35>0.9,"YELLOW — AT RISK","GREEN — ON TRACK")) -> GREEN — ON TRACK

Sheet 53_DRAWS
A1: CONSTRUCTION DRAW SCHEDULE
A3: Draw_ID | B3: Date | C3: Property | D3: Lender | E3: Draw_Amount | F3: Draw_Purpose | G3: Work_Completed_% | H3: Inspector_Approved | I3: Funded | J3: Draw_Number | K3: Cumulative_Draws | L3: Remaining_Budget | M3: Notes
A4: DR001 | B4: 05/15/2026 | C4: 502 Buckley | D4: FHA/Personal | E4: 3500 | F4: Demo phase materials — lumber, dumpster | G4: 70 | H4: No | I4: Yes | J4: 1 | K4: 3500 | L4: =90000-K4 -> 86500 | M4: Initial materials draw

Sheet 54_HOLDING_COSTS
A1: HOLDING COSTS TRACKER
A3: HC_ID | B3: Property | C3: Month | D3: Mortgage | E3: Property_Tax | F3: Insurance | G3: Utilities | H3: HOA | I3: Other | J3: Total_Monthly | K3: Cumulative_Total | L3: Notes
A4: HC001 | B4: 502 Buckley | C4: May 2026 | D4: 750 | E4: 150 | F4: 100 | G4: 80 | H4: 0 | I4: 0 | J4: =SUM(D4:I4) -> 1080 | K4: =J4 -> 1080

Sheet 55_RENTS
A1: RENT ROLL — Rental Income Tracker
A3: Rent_ID | B3: Property | C3: Unit | D3: Tenant_Name | E3: Lease_Start | F3: Lease_End | G3: Monthly_Rent | H3: Security_Deposit | I3: Deposit_Held | J3: Jan | K3: Feb | L3: Mar | M3: Apr | N3: May | O3: Jun | P3: Jul | Q3: Aug | R3: Sep | S3: Oct | T3: Nov | U3: Dec | V3: Annual_Rent | W3: Collected_YTD | X3: Notes
A4: RENT001 | B4: 502 Buckley | C4: Unit 1 | D4: VACANT | G4: 1400 | I4: 0 | J4: 0 | K4: 0 | L4: 0 | M4: 0 | N4: 0 | O4: 0 | P4: 0 | Q4: 0 | R4: 0 | S4: 0 | T4: 0 | U4: 0 | V4: =SUM(J4:U4) -> 0 | W4: =SUM(J4:N4) -> 0 | X4: Pending rehab completion — est. rental ready Q4 2026

Sheet 56_CAPEX
A1: CAPITAL EXPENDITURES — Asset Register
A3: CapEx_ID | B3: Date | C3: Property | D3: Description | E3: Amount | F3: Asset_Class | G3: Useful_Life | H3: Annual_Depreciation | I3: Accumulated_Depr | J3: Book_Value | K3: Capitalized | L3: Notes
A4: CE001 | B4: 05/01/2026 | C4: 502 Buckley | D4: Building purchase | E4: 97900 | F4: Residential RE | G4: 27.5 | H4: =E4/G4 -> 3560 | I4: 0 | J4: =E4-I4 -> 97900 | K4: Yes | L4: FHA purchase allocation
A5: CE002 | B5: 05/01/2026 | C5: 502 Buckley | D5: Land purchase | E5: 16100 | F5: Land | G5: 0 | H5: 0 | I5: 0 | J5: =E5 -> 16100 | K5: Yes | L5: Land not depreciated

Sheet 57_DISPOSITIONS
A1: DISPOSITIONS — Property Sales Log
A3: Disp_ID | B3: Property | C3: Sale_Date | D3: Sale_Price | E3: Purchase_Price | F3: Rehab_Cost | G3: Holding_Costs | H3: Selling_Costs | I3: Total_Costs | J3: Net_Profit | K3: ROI | L3: Annualized_ROI | M3: Hold_Days | N3: Exit_Type | O3: Buyer | P3: Notes
A4: [No dispositions yet]

Sheet 60_WHOLESALE_ANALYZER
A1: WHOLESALE DEAL ANALYZER — Dynasty Accounting OS
A3: INPUTS (Blue = Editable)
A4: Property Address | D4: [ENTER ADDRESS]
A5: ARV (After Repair Value) | D5: 150000
A6: Purchase Price | D6: 60000
A7: Assignment Fee Target | D7: 15000
A8: Marketing Cost | D8: 2000
A9: Inspection Cost | D9: 500
A10: Other Costs | D10: 300
A12: CALCULATIONS
A13: MAO (70% Rule) | D13: =D5*0.7 -> 105000
A14: Max Purchase Price | D14: =D5*0.65 -> 97500
A15: Gross Spread | D15: =D5-D6 -> 90000
A16: Total Costs | D16: =D8+D9+D10 -> 2800
A17: Net Assignment Fee | D17: =D7-D16 -> 12200
A18: ROI on Marketing | D18: =IF(D16=0,0,D17/D16) -> 4.3571429
A19: DECISION | D19: =IF(D6<=D5*0.65,"GO — DEAL WORKS","NO GO — PRICE TOO HIGH") -> GO — DEAL WORKS
A22: WHOLESALE PIPELINE
A23: Lead | B23: Status | C23: ARV | D23: Asking | E23: Offer | F23: Assignment_Fee | G23: Mktg_Cost | H23: Net_Profit | I23: Decision

Sheet 61_FLIP_ANALYZER
A1: FIX & FLIP ANALYZER — 502 Buckley Analysis
A3: INPUTS — 502 Buckley, St. Louis MO
A4: Property Address | D4: 502 Buckley, St. Louis MO 63137
A5: Purchase Price | D5: 114000
A6: Closing Costs — Purchase | D6: 4500
A7: Rehab Budget | D7: 90000
A8: Holding Period (months) | D8: 9
A9: Monthly Holding Cost | D9: 1080
A10: Selling Price (ARV) | D10: 200000
A11: Realtor Commission % | D11: 0.06
A12: Closing Costs Sale % | D12: 0.03
A13: Other Selling Costs | D13: 2000
A15: FLIP ANALYSIS
A16: Total Acquisition Cost | D16: =D5+D6 -> 118500
A17: Total Rehab Cost | D17: =D7 -> 90000
A18: Total Holding Costs | D18: =D9*D8 -> 9720
A19: Total Selling Costs | D19: =D10*D11+D10*D12+D13 -> 20000
A20: TOTAL PROJECT COST | D20: =D16+D17+D18+D19 -> 238220
A21: NET PROFIT | D21: =D10-D20 -> -38220
A22: ROI | D22: =IF(D20=0,0,D21/D20) -> -0.16043993
A23: Annualized ROI | D23: =IF(D8=0,0,(1+D22)^(12/D8)-1) -> -0.20798082
A24: DECISION | D24: =IF(D21>30000,"STRONG FLIP",IF(D21>15000,"MARGINAL FLIP","DO NOT FLIP")) -> DO NOT FLIP

Sheet 62_BRRR_ANALYZER
A1: BRRR ANALYZER — Buy, Rehab, Rent, Refinance, Repeat
A3: INPUTS — 502 Buckley BRRR Analysis
A4: Purchase Price | D4: 114000
A5: Closing Costs | D5: 4500
A6: Rehab Cost | D6: 90000
A7: ARV After Rehab | D7: 200000
A8: Monthly Rent | D8: 1400
A9: Vacancy Rate % | D9: 0.05
A10: Operating Expense % | D10: 0.35
A11: Refinance LTV % | D11: 0.75
A12: Refinance Interest Rate % | D12: 0.07
A13: Refinance Term (years) | D13: 30
A14: Total Holding Costs During Rehab | D14: 9720
A16: BRRR ANALYSIS
A17: Total Investment (All-In) | D17: =D4+D5+D6+D14 -> 218220
A18: Refinance Amount | D18: =D7*D11 -> 150000
A19: Monthly Mortgage (Refi) | D19: =-PMT(D12/12,D13*12,D18) -> 997.95374
A20: Effective Monthly Rent | D20: =D8*(1-D9) -> 1330
A21: Monthly Operating Expenses | D21: =D20*D10 -> 465.5
A22: Monthly NOI | D22: =D20-D21 -> 864.5
A23: Monthly Cash Flow | D23: =D22-D19 -> -133.45374
A24: Annual Cash Flow | D24: =D23*12 -> -1601.4449
A25: Cash Left in Deal | D25: =D17-D18 -> 68220
A26: Cash-on-Cash Return | D26: =IF(D25>0,D24/D25,"INFINITE — Full Refi") -> -0.023474713
A27: Cap Rate | D27: =IF(D7>0,(D22*12)/D7,0) -> 0.05187
A28: DSCR | D28: =IF(D19>0,D22/D19,0) -> 0.86627262
A29: Equity Created | D29: =D7-(D4+D5+D6) -> -8500
A30: Cash Recovered | D30: =D18-(D4+D5+D6) -> -58500
A31: DECISION | D31: =IF(D22/D19>=1.25,IF(D23>=0,"STRONG BRRR — GO","BRRR WORKS — WEAK CASH FLOW"),"DSCR TOO LOW — RENEGOTIATE") -> DSCR TOO LOW — RENEGOTIATE

Sheet 63_DEVELOPMENT_ANALYZER
A1: DEVELOPMENT DEAL ANALYZER
A3: INPUTS
A4: Land Cost | D4: 0
A5: Soft Costs (permits, arch, eng) | D5: 0
A6: Hard Construction Costs | D6: 0
A7: Financing Costs | D7: 0
A8: Contingency % | D8: 0.1
A9: Number of Units | D9: 1
A10: Projected Sale Price per Unit | D10: 0
A12: DEVELOPMENT ANALYSIS
A13: Base Development Cost | D13: =D4+D5+D6+D7 -> 0
A14: Contingency Reserve | D14: =D13*D8 -> 0
A15: TOTAL DEVELOPMENT COST | D15: =D13+D14 -> 0
A16: Cost Per Unit | D16: =IF(D9>0,D15/D9,0) -> 0
A17: Gross Development Value (GDV) | D17: =D10*D9 -> 0
A18: Development Profit | D18: =D17-D15 -> 0
A19: Development Margin | D19: =IF(D17=0,0,D18/D17) -> 0
A20: ROI | D20: =IF(D15=0,0,D18/D15) -> 0
A21: DECISION | D21: =IF(D19>0.2,"VIABLE PROJECT",IF(D19>0.1,"MARGINAL","NOT VIABLE")) -> NOT VIABLE

Sheet 64_LAND_ANALYZER
A1: LAND DEAL ANALYZER
A3: INPUTS
A4: Purchase Price | D4: 0
A5: Entitlement Costs | D5: 0
A6: Carrying Costs / Month | D6: 0
A7: Hold Period (months) | D7: 12
A8: Target Sale Price | D8: 0
A9: Assignment Fee Option | D9: 0
A11: LAND ANALYSIS
A12: Total Carrying Costs | D12: =D6*D7 -> 0
A13: Total Cost (Hold) | D13: =D4+D5+D12 -> 0
A14: Net Profit (Sell) | D14: =D8-D13 -> 0
A15: ROI (Sell) | D15: =IF(D13=0,0,D14/D13) -> 0
A16: Net Profit (Assign) | D16: =D9-(D5+D6*3) -> 0
A17: ROI (Assign) | D17: =IF(D4=0,0,D16/D4) -> 0
A18: Annualized ROI | D18: =IF(D7=0,0,(1+D14/IF(D13=0,1,D13))^(12/D7)-1) -> 0

Sheet 70_INVESTORS
A1: INVESTOR REGISTRY — Dynasty Accounting OS
A3: Investor_ID | B3: Full_Name | C3: Entity | D3: Email | E3: Phone | F3: Accredited | G3: Capital_Committed | H3: Capital_Called | I3: Capital_Returned | J3: Pref_Return_% | K3: Profit_Split_% | L3: Current_Balance | M3: Status | N3: Notes
A4: INV001 | B4: Private Lender 1 | C4: [TBD] | F4: Yes | G4: 50000 | H4: 0 | I4: 0 | J4: 0.08 | K4: 0.3 | L4: 0 | M4: Active | N4: Hard money / private lender potential

Sheet 71_CAPITAL_STACK
A1: CAPITAL STACK — 502 Buckley
A3: Tranche | B3: Source | C3: Type | D3: Amount | E3: Rate_% | F3: Term | G3: LTV_% | H3: Position | I3: Monthly_Payment | J3: Total_Cost | K3: Notes
A4: Senior Debt | B4: FHA Mortgage | C4: Debt | D4: 114000 | E4: 0.065 | F4: 30 years | G4: =D4/200000 -> 0.57 | H4: 1st Lien | I4: 750 | J4: =I4*360 -> 270000 | K4: FHA purchase loan at 6.5%
A5: Equity | B5: Owner Capital | C5: Equity | D5: 18500 | E5: 0 | F5: N/A | G5: N/A | H5: Equity | I5: 0 | J5: N/A | K5: Owner equity + closing costs
A7: TOTALS | D7: =SUM(D4:D6) -> 132500 | I7: =SUM(I4:I6) -> 750

Sheet 72_WATERFALL
A1: DISTRIBUTION WATERFALL — 3-Tier Structure
A3: WATERFALL INPUTS
A4: Total Distributions Available | D4: 0
A5: Total Investor Capital Invested | D5: 50000
A6: Preferred Return Rate % | D6: 0.08
A7: Investor Profit Share % | D7: 0.3
A8: Owner Profit Share % | D8: 0.7
A10: WATERFALL DISTRIBUTION
A11: TIER 1: Return of Capital | D11: =MIN(D4,D5) -> 0
A12: Remaining After Tier 1 | D12: =MAX(0,D4-D11) -> 0
A13: TIER 2: Preferred Return (8% annualized) | D13: =MIN(D12,D5*D6) -> 0
A14: Remaining After Tier 2 | D14: =MAX(0,D12-D13) -> 0
A15: TIER 3: Investor Profit Share (30%) | D15: =D14*D7 -> 0
A16: Owner Profit Share (70%) | D16: =D14*D8 -> 0
A18: INVESTOR TOTAL | D18: =D11+D13+D15 -> 0
A19: OWNER TOTAL | D19: =D16 -> 0
A20: GRAND TOTAL CHECK | D20: =D18+D19 -> 0

Sheet 73_DISTRIBUTIONS
A1: DISTRIBUTION HISTORY
A3: Dist_ID | B3: Date | C3: Property_Fund | D3: Investor_ID | E3: Investor_Name | F3: Dist_Type | G3: Amount | H3: ROC | I3: Preferred | J3: Profit | K3: Cumulative | L3: Notes
A4: [No distributions yet]

Sheet 74_INVESTOR_REPORTS
A1: INVESTOR SUMMARY REPORT — Dynasty Accounting OS
A3: Report Date: 05/29/2026 | Prepared by: Dynasty Accounting OS v1.0
A5: Investor_ID | B5: Name | C5: Capital_Invested | D5: Distributions | E5: Current_Balance | F5: Pref_Return_Earned | G5: IRR | H5: Status
A6: INV001 | B6: Private Lender 1 | C6: 50000 | D6: 0 | E6: 50000 | F6: 0 | G6: N/A | H6: Active

Sheet 80_AI_DEAL_SCORING
A1: AI DEAL SCORING ENGINE — TROOPER_ACCOUNTANT
A3: STATUS: Placeholder formulas active | Connect AI API for enhanced ML scoring | All scores calculated via weighted formula matrix
A5: Deal_ID | B5: Address | C5: Deal_Type | D5: ARV | E5: Purchase | F5: Rehab | G5: Spread | H5: Margin_% | I5: DSCR | J5: Cash_Flow | K5: Score | L5: Grade | M5: AI_Recommendation
A6: DEAL001 | B6: 502 Buckley, St. Louis MO | C6: BRRR | D6: 200000 | E6: 114000 | F6: 90000 | G6: =D6-E6 -> 86000 | H6: =IF(D6>0,(D6-E6-F6)/D6,0) -> -0.02 | I6: 0 | J6: 0 | K6: =MAX(0,MIN(100,H6*100*0.4+IF(I6>=1.25,30,I6*24)+IF(J6>0,30,0))) -> 0 | L6: =IF(K6>=80,"A",IF(K6>=70,"B",IF(K6>=60,"C","D"))) -> D | M6: =IF(L6="A","STRONG BUY",IF(L6="B","REVIEW",IF(L6="C","PASS","AVOID"))) -> AVOID

Sheet 81_AI_FORECASTING
A1: 13-WEEK ROLLING CASH FORECAST — Dynasty Accounting OS
A3: Week | B3: Week_Start | C3: Week_End | D3: Beginning_Balance | E3: Expected_Inflows | F3: Expected_Outflows | G3: Net_Change | H3: Ending_Balance | I3: Alert
A4: 1 | B4: 05/29/2026 | C4: 06/04/2026 | D4: 17200 | E4: 0 | F4: 3800 | G4: =E4-F4 -> -3800 | H4: =D4+G4 -> 13400 | I4: =IF(H4<5000,"CRITICAL — LOW CASH",IF(H4<15000,"WARNING — MONITOR","OK")) -> WARNING — MONITOR
A5: 2 | B5: 06/05/2026 | C5: 06/11/2026 | D5: =H4 -> 13400 | E5: 0 | F5: 1500 | G5: =E5-F5 -> -1500 | H5: =D5+G5 -> 11900 | I5: =IF(H5<5000,"CRITICAL — LOW CASH",IF(H5<15000,"WARNING — MONITOR","OK")) -> WARNING — MONITOR
A6: 3 | B6: 06/12/2026 | C6: 06/18/2026 | D6: =H5 -> 11900 | E6: 5000 | F6: 8500 | G6: =E6-F6 -> -3500 | H6: =D6+G6 -> 8400 | I6: =IF(H6<5000,"CRITICAL — LOW CASH",IF(H6<15000,"WARNING — MONITOR","OK")) -> WARNING — MONITOR
A7: 4 | B7: 06/19/2026 | C7: 06/25/2026 | D7: =H6 -> 8400 | E7: 5000 | F7: 1500 | G7: =E7-F7 -> 3500 | H7: =D7+G7 -> 11900 | I7: =IF(H7<5000,"CRITICAL — LOW CASH",IF(H7<15000,"WARNING — MONITOR","OK")) -> WARNING — MONITOR
A8: 5 | B8: 06/26/2026 | C8: 07/02/2026 | D8: =H7 -> 11900 | E8: 5000 | F8: 8500 | G8: =E8-F8 -> -3500 | H8: =D8+G8 -> 8400 | I8: =IF(H8<5000,"CRITICAL — LOW CASH",IF(H8<15000,"WARNING — MONITOR","OK")) -> WARNING — MONITOR
A9: 6 | B9: 07/03/2026 | C9: 07/09/2026 | D9: =H8 -> 8400 | E9: 5000 | F9: 1500 | G9: =E9-F9 -> 3500 | H9: =D9+G9 -> 11900 | I9: =IF(H9<5000,"CRITICAL — LOW CASH",IF(H9<15000,"WARNING — MONITOR","OK")) -> WARNING — MONITOR
A10: 7 | B10: 07/10/2026 | C10: 07/16/2026 | D10: =H9 -> 11900 | E10: 5000 | F10: 8500 | G10: =E10-F10 -> -3500 | H10: =D10+G10 -> 8400 | I10: =IF(H10<5000,"CRITICAL — LOW CASH",IF(H10<15000,"WARNING — MONITOR","OK")) -> WARNING — MONITOR
A11: 8 | B11: 07/17/2026 | C11: 07/23/2026 | D11: =H10 -> 8400 | E11: 5000 | F11: 1500 | G11: =E11-F11 -> 3500 | H11: =D11+G11 -> 11900 | I11: =IF(H11<5000,"CRITICAL — LOW CASH",IF(H11<15000,"WARNING — MONITOR","OK")) -> WARNING — MONITOR
A12: 9 | B12: 07/24/2026 | C12: 07/30/2026 | D12: =H11 -> 11900 | E12: 5000 | F12: 8500 | G12: =E12-F12 -> -3500 | H12: =D12+G12 -> 8400 | I12: =IF(H12<5000,"CRITICAL — LOW CASH",IF(H12<15000,"WARNING — MONITOR","OK")) -> WARNING — MONITOR
A13: 10 | B13: 07/31/2026 | C13: 08/06/2026 | D13: =H12 -> 8400 | E13: 5000 | F13: 1500 | G13: =E13-F13 -> 3500 | H13: =D13+G13 -> 11900 | I13: =IF(H13<5000,"CRITICAL — LOW CASH",IF(H13<15000,"WARNING — MONITOR","OK")) -> WARNING — MONITOR
A14: 11 | B14: 08/07/2026 | C14: 08/13/2026 | D14: =H13 -> 11900 | E14: 5000 | F14: 3800 | G14: =E14-F14 -> 1200 | H14: =D14+G14 -> 13100 | I14: =IF(H14<5000,"CRITICAL — LOW CASH",IF(H14<15000,"WARNING — MONITOR","OK")) -> WARNING — MONITOR
A15: 12 | B15: 08/14/2026 | C15: 08/20/2026 | D15: =H14 -> 13100 | E15: 5000 | F15: 1500 | G15: =E15-F15 -> 3500 | H15: =D15+G15 -> 16600 | I15: =IF(H15<5000,"CRITICAL — LOW CASH",IF(H15<15000,"WARNING — MONITOR","OK")) -> OK
A16: 13 | B16: 08/21/2026 | C16: 08/27/2026 | D16: =H15 -> 16600 | E16: 5000 | F16: 1500 | G16: =E16-F16 -> 3500 | H16: =D16+G16 -> 20100 | I16: =IF(H16<5000,"CRITICAL — LOW CASH",IF(H16<15000,"WARNING — MONITOR","OK")) -> OK

Sheet 82_AI_ANOMALIES
A1: AI ANOMALY DETECTION — Expense Monitor
A3: STATUS: Monitoring active | Connect to live transaction feed for real-time anomaly detection | Threshold: >50% variance from average
A5: Detection_Date | B5: Account | C5: Category | D5: Amount | E5: Avg_Amount | F5: Variance_% | G5: Anomaly_Flag | H5: Severity | I5: Notes
A6: 05/25/2026 | B6: 6120 | C6: Marketing Software | D6: 299 | E6: 299 | F6: =IF(E6=0,0,(D6-E6)/E6) -> 0 | G6: =IF(ABS(F6)>0.5,"FLAGGED","Normal") -> Normal | H6: =IF(ABS(F6)>1,"HIGH",IF(ABS(F6)>0.5,"MEDIUM","LOW")) -> LOW
A7: 05/20/2026 | B7: 5110 | C7: Rehab Materials | D7: 3500 | E7: 3500 | F7: =IF(E7=0,0,(D7-E7)/E7) -> 0 | G7: =IF(ABS(F7)>0.5,"FLAGGED","Normal") -> Normal | H7: =IF(ABS(F7)>1,"HIGH",IF(ABS(F7)>0.5,"MEDIUM","LOW")) -> LOW

Sheet 83_AI_ASSISTANT
A1: AI ACCOUNTING ASSISTANT — TROOPER_ACCOUNTANT
A3: TROOPER_ACCOUNTANT | Institutional-grade AI accounting assistant for Dynasty Accounting OS
A5: CAPABILITY | D5: DESCRIPTION
A6: Auto-categorize transactions | D6: Connect to bank feed API — auto-matches transactions to COA
A7: Detect expense anomalies | D7: Flags variances >50% from historical average per category
A8: Forecast 13-week cash flow | D8: Uses budget + AR/AP aging to project weekly cash position
A9: Analyze property performance | D9: Calculates ROI, DSCR, Cap Rate, Cash-on-Cash for all properties
A10: Score deals (0-100) | D10: Weighted scoring: margin 40%, DSCR 30%, cash flow 30%
A11: Prepare lender packages | D11: Generates formatted lender-ready financial summaries
A12: Prepare investor reports | D12: Generates distribution statements and portfolio reports
A13: Monitor KPI drift | D13: Alerts when KPIs deviate >10% from targets
A14: Generate financial narratives | D14: Creates plain-English summaries of financial performance
A15: Simulate scenarios | D15: Models best/base/worst case scenarios for each property
A18: API INTEGRATION CONFIGURATION
A19: Function | B19: Status | C19: API_Endpoint | D19: Last_Run | E19: Notes
A20: Transaction Categorization | B20: PLACEHOLDER — Configure API endpoint
A21: Anomaly Detection | B21: PLACEHOLDER — Configure API endpoint
A22: Cash Forecasting | B22: PLACEHOLDER — Configure API endpoint
A23: Deal Scoring | B23: PLACEHOLDER — Configure API endpoint
A24: Report Generation | B24: PLACEHOLDER — Configure API endpoint

Sheet 90_KPI_DASHBOARD
A1: DYNASTY ACCOUNTING OS — KPI COMMAND CENTER
A3: CASH & FINANCIAL METRICS
A4: CASH AVAILABLE | C4: MONTHLY REVENUE | E4: MONTHLY EXPENSES | G4: NET INCOME MTD
A5: 17200 | C5: 0 | E5: 11799 | G5: -11799
A6: Bank balance | C6: MTD revenue | E6: MTD expenses | G6: Revenue - Expenses
A7: REAL ESTATE PORTFOLIO METRICS
A8: ACTIVE PROPERTIES | C8: PORTFOLIO ARV | E8: PORTFOLIO EQUITY | G8: REHAB IN PROGRESS
A9: 1 | C9: 200000 | E9: 86000 | G9: 1
A10: Count | C10: Total ARV | E10: ARV - Debt | G10: Properties
A11: OBLIGATIONS & PIPELINE
A12: TOTAL DEBT | C12: MONTHLY DEBT SERVICE | E12: AP BALANCE | G12: AR BALANCE
A13: 114000 | C13: 750 | E13: 8000 | G13: 15000
A14: Mortgages + loans | C14: All loan payments | E14: Total owed to vendors | G14: Total owed to company
A15: DEAL PIPELINE
A16: WHOLESALE PIPELINE | C16: FLIP PIPELINE | E16: BRRR PIPELINE | G16: MTD ASSIGN FEES
A17: $0 | C17: $114K | E17: $114K | G17: $0
A18: Active deals | C18: 502 Buckley | E18: 502 Buckley | G18: This month

Sheet 91_CASH_FORECAST
A1: 12-MONTH CASH FORECAST — FY 2026
A3: Month | B3: Beginning_Balance | C3: Revenue | D3: Expenses | E3: Net_Change | F3: Ending_Balance | G3: Notes
A4: Jan 2026 | B4: 0 | C4: 0 | D4: 0 | E4: =C4-D4 -> 0 | F4: =B4+E4 -> 0 | G4: Rehab in progress
A5: Feb 2026 | B5: =F4 -> 0 | C5: 0 | D5: 0 | E5: =C5-D5 -> 0 | F5: =B5+E5 -> 0 | G5: Rehab in progress
A6: Mar 2026 | B6: =F5 -> 0 | C6: 0 | D6: 0 | E6: =C6-D6 -> 0 | F6: =B6+E6 -> 0 | G6: Rehab in progress
A7: Apr 2026 | B7: =F6 -> 0 | C7: 0 | D7: 0 | E7: =C7-D7 -> 0 | F7: =B7+E7 -> 0 | G7: Rehab in progress
A8: May 2026 | B8: =F7 -> 0 | C8: 500 | D8: 11799 | E8: =C8-D8 -> -11299 | F8: =B8+E8 -> -11299 | G8: Rehab in progress
A9: Jun 2026 | B9: =F8 -> -11299 | C9: 5000 | D9: 11799 | E9: =C9-D9 -> -6799 | F9: =B9+E9 -> -18098 | G9: Est. wholesale activity
A10: Jul 2026 | B10: =F9 -> -18098 | C10: 5000 | D10: 11799 | E10: =C10-D10 -> -6799 | F10: =B10+E10 -> -24897 | G10: Est. wholesale activity
A11: Aug 2026 | B11: =F10 -> -24897 | C11: 5000 | D11: 5000 | E11: =C11-D11 -> 0 | F11: =B11+E11 -> -24897 | G11: Est. wholesale activity
A12: Sep 2026 | B12: =F11 -> -24897 | C12: 5000 | D12: 5000 | E12: =C12-D12 -> 0 | F12: =B12+E12 -> -24897 | G12: Est. wholesale activity
A13: Oct 2026 | B13: =F12 -> -24897 | C13: 10000 | D13: 5000 | E13: =C13-D13 -> 5000 | F13: =B13+E13 -> -19897 | G13: Projected
A14: Nov 2026 | B14: =F13 -> -19897 | C14: 10000 | D14: 5000 | E14: =C14-D14 -> 5000 | F14: =B14+E14 -> -14897 | G14: Projected
A15: Dec 2026 | B15: =F14 -> -14897 | C15: 10000 | D15: 5000 | E15: =C15-D15 -> 5000 | F15: =B15+E15 -> -9897 | G15: Projected

Sheet 92_NET_WORTH_TRACKER
A1: NET WORTH TRACKER — Shylow Thompson LLC
A3: Date | B3: Cash_Total | C3: Property_Values | D3: Other_Assets | E3: Total_Assets | F3: Total_Liabilities | G3: Net_Worth | H3: Change | I3: Notes
A4: 05/29/2026 | B4: 17200 | C4: 200000 | D4: 0 | E4: =B4+C4+D4 -> 217200 | F4: 122299 | G4: =E4-F4 -> 94901 | H4: 0 | I4: Inception — Dynasty Accounting OS v1.0

Sheet 93_PORTFOLIO_ANALYTICS
A1: PORTFOLIO ANALYTICS — Dynasty Accounting OS
A3: PROPERTY PERFORMANCE TABLE
A4: Property | B4: Purchase | C4: ARV | D4: Equity | E4: NOI | F4: DSCR | G4: Cap_Rate | H4: Cash_Flow | I4: Status | J4: Grade
A5: 502 Buckley | B5: 114000 | C5: 200000 | D5: =C5-B5-114000 -> -28000 | E5: 0 | F5: 0 | G5: 0 | H5: 0 | I5: Active — Rehab | J5: B
A7: REVENUE MIX (YTD)
A8: Wholesale Assignment Fees | B8: 0
A9: Flip Profits | B9: 0
A10: Rental Income | B10: 0
A11: Consulting/Other | B11: 500
A12: TOTAL REVENUE YTD | B12: =SUM(B8:B11) -> 500
A14: PORTFOLIO KPIs
A15: Total Properties | B15: 1
A16: Total Portfolio ARV | B16: $200,000
A17: Total Debt | B17: $114,000
A18: Total Equity | B18: $86,000
A19: Avg Cap Rate | B19: 0.0%
A20: Portfolio DSCR | B20: 0.00x

Sheet 94_EXECUTIVE_REPORT
A1: DYNASTY ACCOUNTING OS — EXECUTIVE SUMMARY REPORT
A2: Shylow Thompson LLC | Period: YTD 2026 | Generated: 05/29/2026 | Dynasty Accounting OS v1.0
A4: 1. COMPANY OVERVIEW
A5: Entity | B5: Shylow Thompson LLC — Real Estate Investment Company
A6: State | B6: Missouri
A7: Business Lines | B7: Wholesale, BRRR, Flip, Development, Rentals
A8: Accounting System | B8: Dynasty Accounting OS v1.0 — Accrual Basis
A9: Reporting Period | B9: January 1, 2026 — May 29, 2026
A11: 2. FINANCIAL HIGHLIGHTS
A12: Total Revenue YTD | B12: $500
A13: Total Expenses YTD | B13: $11,799
A14: Net Income YTD | B14: ($11,299)
A15: Cash Position | B15: $17,200
A16: Note | B16: Net loss reflects startup + rehab investment phase — expected
A18: 3. BALANCE SHEET SUMMARY
A19: Total Assets | B19: $217,200
A20: Total Liabilities | B20: $122,299
A21: Net Worth / Equity | B21: $94,901
A22: Primary Asset | B22: 502 Buckley — ARV $200,000
A24: 4. REAL ESTATE PORTFOLIO
A25: Active Properties | B25: 1 — 502 Buckley, St. Louis MO 63137
A26: Status | B26: Active Rehabilitation
A27: Purchase Price | B27: $114,000
A28: Rehab Budget | B28: $90,000
A29: Rehab Actual | B29: $11,500 (12.8% complete)
A30: Estimated ARV | B30: $200,000
A31: Exit Strategy | B31: BRRR — Refinance + Hold as Rental
A33: 5. KEY RISKS & OPPORTUNITIES
A34: Risk 1 | B34: Rehab cost overruns — monitor weekly vs 90K budget
A35: Risk 2 | B35: Cash position — 17K available vs 90K rehab remaining
A36: Opportunity 1 | B36: 502 Buckley BRRR — est. $86K equity creation
A37: Opportunity 2 | B37: Wholesale pipeline — 0 active deals, needs marketing
A40: 6. 90-DAY OUTLOOK
A41: Rehab Completion Target | B41: August 2026 (est.)
A42: Estimated Cash Need | B42: $78,500 additional rehab funding
A43: Revenue Opportunity | B43: $10,000-$25,000 wholesale deals
A44: Next Action | B44: Secure rehab financing / private lender capital
A48: DISCLAIMER: This report is for internal management use only. Generated by Dynasty Accounting OS v1.0 | Shylow Thompson LLC Confidential
